Workbook

Sheet Reports
A1: Report_ID | B1: PZN | C1: ENR | D1: Meldungsart | E1: Beginn | F1: Ende | G1: Dauer (Tage) | H1: Datum der Erstmeldung | I1: Datum der letzten Meldung | J1: Art des Grundes | K1: Arzneimittlbezeichnung | L1: Atc Code | M1: Wirkstoffe | N1: Krankenhausrelevant | O1: Zulassungsinhaber | P1: Telefon | Q1: E-Mail | R1: Grund | S1: Anm. zum Grund | T1: Alternativpräparat | U1: Info an Fachkreise | V1: Darreichungsform | W1: Obergruppe | X1: Obergruppe ATC-Code
A2: 1852 | B2: 01335381, 02421349 | C2: 70733 | D2: Löschmeldung | E2: 44929 | F2: 44965 | G2: =F2-E2 -> 36 | H2: 44938 | I2: 44967 | J2: Sonstige | K2: Ampho-Moronal Lutschtabletten | L2: A01AB04 | M2: Amphotericin B | N2: ja | O2: Dermapharm Aktiengesellschaft | Q2: service@dermapharm.de | R2: Unzureichende Produktionskapazitäten | S2: Die Packungsgröße 50 Stk. (PZN 02421332) ist voraussichtlich während der Dauer des Lieferengpasses verfügbar. | U2: Nein | V2: Lutschtablette | W2: =VLOOKUP(Table1[[#This Row],[Obergruppe ATC-Code]],Tabelle3!$A$2:$B$100,2) -> STOMATOLOGIKA | X2: =LEFT(Table1[[#This Row],[Atc Code]],3) -> A01
A3: 1851 | B3: 01335381, 02421332, 02421349 | C3: 70733 | D3: Löschmeldung | E3: 45141 | F3: 45187 | G3: =F3-E3 -> 46 | H3: 45146 | I3: 45190 | J3: Sonstige | K3: Ampho-Moronal Lutschtabletten | L3: A01AB04 | M3: Amphotericin B | N3: nein | O3: Dermapharm Aktiengesellschaft | P3: 498964186105 | Q3: yvonne.hinterstocker@dermapharm.com | R3: Unzureichende Produktionskapazitäten | U3: Nein | V3: Lutschtablette | W3: =VLOOKUP(Table1[[#This Row],[Obergruppe ATC-Code]],Tabelle3!$A$2:$B$100,2) -> STOMATOLOGIKA | X3: =LEFT(Table1[[#This Row],[Atc Code]],3) -> A01
A4: 1648 | B4: 00046367, 00046350 | C4: 2140871 | D4: Löschmeldung | E4: 42887 | F4: 42947 | G4: =F4-E4 -> 60 | H4: 42892 | I4: 42929 | J4: Produktionsproblem | K4: Metronidazol-ratiopharm 400 mg Tabletten | L4: A01AB17, G01AF01, J01XD01 | M4: Metronidazol | N4: ja | O4: ratiopharm GmbH | P4: 0800 800 50 13 | Q4: klinikteam@ratiopharm.de | R4: Herstellerwechsel | U4: Nein | V4: Tablette | W4: =VLOOKUP(Table1[[#This Row],[Obergruppe ATC-Code]],Tabelle3!$A$2:$B$100,2) -> STOMATOLOGIKA | X4: =LEFT(Table1[[#This Row],[Atc Code]],3) -> A01
A5: 1921 | B5: 01865653 | C5: 2140512 | D5: Löschmeldung | E5: 43891 | F5: 44074 | G5: =F5-E5 -> 183 | H5: 43910 | I5: 44075 | J5: Produktionsproblem | K5: Metronidazol 400 mg - 1 A Pharma | L5: A01AB17, G01AF01, J01XD01 | M5: Metronidazol | N5: nein | O5: 1 A Pharma GmbH | P5: 089/61388250 | Q5: info@1apharma.com | R5: Herstellerwechsel | U5: Nein | V5: Tablette | W5: =VLOOKUP(Table1[[#This Row],[Obergruppe ATC-Code]],Tabelle3!$A$2:$B$100,2) -> STOMATOLOGIKA | X5: =LEFT(Table1[[#This Row],[Atc Code]],3) -> A01
A6: 1647 | B6: 00046367, 00046350 | C6: 2140871 | D6: Löschmeldung | E6: 43983 | F6: 44104 | G6: =F6-E6 -> 121 | H6: 44012 | I6: 44085 | J6: Produktionsproblem | K6: Metronidazol-ratiopharm 400 mg Tabletten | L6: A01AB17, G01AF01, J01XD01 | M6: Metronidazol | N6: ja | O6: ratiopharm GmbH | P6: 0800 / 800 50 13 | Q6: gks-post@ratiopharm.de | R6: Sonstige | U6: Ja | V6: Tablette | W6: =VLOOKUP(Table1[[#This Row],[Obergruppe ATC-Code]],Tabelle3!$A$2:$B$100,2) -> STOMATOLOGIKA | X6: =LEFT(Table1[[#This Row],[Atc Code]],3) -> A01
A7: 2183 | B7: 04913803, 04913826 | C7: 801728 | D7: Löschmeldung | E7: 44228 | F7: 44474 | G7: =F7-E7 -> 246 | H7: 44183 | I7: 44474 | J7: Produktionsproblem | K7: Dontisolon D Mundheilpaste | L7: A01AC54 | M7: Prednisolonacetat | N7: ja | O7: Sanofi-Aventis Deutschland GmbH | P7: 0800 52 52 010 | Q7: medinfo.de@sanofi.com | R7: Probleme bei der Endfreigabe | S7: seit 27.09.21 eingeschränkt lieferfähig | U7: Nein | V7: Paste | W7: =VLOOKUP(Table1[[#This Row],[Obergruppe ATC-Code]],Tabelle3!$A$2:$B$100,2) -> STOMATOLOGIKA | X7: =LEFT(Table1[[#This Row],[Atc Code]],3) -> A01
A8: 632 | B8: 4109633 | C8: 2110381 | D8: Löschmeldung | E8: 43739 | F8: 44074 | G8: =F8-E8 -> 335 | H8: 43740 | I8: 44047 | J8: Produktionsproblem | K8: H2-Blocker-ratiopharm 200 mg/ 2 ml Injektionslösung | L8: A02BA01 | M8: Cimetidinhydrochlorid | N8: ja | O8: ratiopharm GmbH | P8: 0800/800 50 13 | Q8: GKS-Post@ratiopharm.de | R8: Herstellerwechsel | T8: Tagamet 200 mg/2 ml - Einreichungsnummer: 2162647 | U8: Nein | V8: Injektionslösung | W8: =VLOOKUP(Table1[[#This Row],[Obergruppe ATC-Code]],Tabelle3!$A$2:$B$100,2) -> MITTEL BEI SÄURE BEDINGTEN ERKRANKUNGEN | X8: =LEFT(Table1[[#This Row],[Atc Code]],3) -> A02
A9: 3019 | B9: 9083766, 09083772 | C9: 2125706 | D9: Löschmeldung | E9: 44228 | F9: 44316 | G9: =F9-E9 -> 88 | H9: 44249 | I9: 44265 | J9: Sonstige | K9: Cimetidin acis 400 mg | L9: A02BA01 | M9: Cimetidin | N9: nein | O9: acis Arzneimittel GmbH | P9: 089/44232460 | Q9: info@acis.de | R9: Unzureichende Produktionskapazitäten | U9: Nein | V9: Tablette | W9: =VLOOKUP(Table1[[#This Row],[Obergruppe ATC-Code]],Tabelle3!$A$2:$B$100,2) -> MITTEL BEI SÄURE BEDINGTEN ERKRANKUNGEN | X9: =LEFT(Table1[[#This Row],[Atc Code]],3) -> A02
A10: 3009 | B10: 8535752, 08535769 | C10: 2125707 | D10: Löschmeldung | E10: 43862 | F10: 44316 | G10: =F10-E10 -> 454 | H10: 44249 | I10: 44312 | J10: Sonstige | K10: Cimetidin acis 800 mg | L10: A02BA01 | M10: Cimetidin | N10: nein | O10: acis Arzneimittel GmbH | P10: 089/44232460 | Q10: info@acis.de | R10: Unzureichende Produktionskapazitäten | U10: Nein | V10: Tablette | W10: =VLOOKUP(Table1[[#This Row],[Obergruppe ATC-Code]],Tabelle3!$A$2:$B$100,2) -> MITTEL BEI SÄURE BEDINGTEN ERKRANKUNGEN | X10: =LEFT(Table1[[#This Row],[Atc Code]],3) -> A02
A11: 3008 | B11: 8535686, 16771722, 07560162 | C11: 2125705 | D11: Löschmeldung | E11: 43891 | F11: 44316 | G11: =F11-E11 -> 425 | H11: 44249 | I11: 44312 | J11: Sonstige | K11: Cimetidin acis 200mg | L11: A02BA01 | M11: Cimetidin | N11: nein | O11: acis Arzneimittel GmbH | P11: 089/44232460 | Q11: info@acis.de | R11: Unzureichende Produktionskapazitäten | U11: Nein | V11: Tablette | W11: =VLOOKUP(Table1[[#This Row],[Obergruppe ATC-Code]],Tabelle3!$A$2:$B$100,2) -> MITTEL BEI SÄURE BEDINGTEN ERKRANKUNGEN | X11: =LEFT(Table1[[#This Row],[Atc Code]],3) -> A02
A12: 2459 | B12: 09083766, 09083772 | C12: 2125706 | D12: Löschmeldung | E12: 45117 | F12: 45214 | G12: =F12-E12 -> 97 | H12: 45125 | I12: 45215 | J12: Sonstige | K12: Cimetidin acis 400 mg | L12: A02BA01 | M12: Cimetidin | N12: nein | O12: acis Arzneimittel GmbH | P12: 8944232460 | Q12: Medwiss.Acis@dermapharm.com | R12: Sonstige | U12: Nein | V12: Tablette | W12: =VLOOKUP(Table1[[#This Row],[Obergruppe ATC-Code]],Tabelle3!$A$2:$B$100,2) -> MITTEL BEI SÄURE BEDINGTEN ERKRANKUNGEN | X12: =LEFT(Table1[[#This Row],[Atc Code]],3) -> A02
A13: 2390 | B13: 08535752, 08535769 | C13: 2125707 | D13: Löschmeldung | E13: 45120 | F13: 45214 | G13: =F13-E13 -> 94 | H13: 45125 | I13: 45215 | J13: Sonstige | K13: Cimetidin acis 800 mg | L13: A02BA01 | M13: Cimetidin | N13: nein | O13: acis Arzneimittel GmbH | P13: 8944232460 | Q13: Medwiss.Acis@dermapharm.com | R13: Sonstige | U13: Nein | V13: Tablette | W13: =VLOOKUP(Table1[[#This Row],[Obergruppe ATC-Code]],Tabelle3!$A$2:$B$100,2) -> MITTEL BEI SÄURE BEDINGTEN ERKRANKUNGEN | X13: =LEFT(Table1[[#This Row],[Atc Code]],3) -> A02
A14: 3030 | B14: 7581514 | C14: 2123230 | D14: Löschmeldung | E14: 43739 | F14: 44196 | G14: =F14-E14 -> 457 | H14: 43756 | I14: 44035 | J14: Produktionsproblem | K14: Ranitic injekt | L14: A02BA02 | M14: Ranitidinhydrochlorid | N14: ja | O14: H e x a l Aktiengesellschaft | P14: 0800-4392527 | Q14: service@hexal.com | R14: Herstellerwechsel | U14: Ja | V14: Konzentrat zur Herstellung einer Injektionslösung oder Infusionslösung | W14: =VLOOKUP(Table1[[#This Row],[Obergruppe ATC-Code]],Tabelle3!$A$2:$B$100,2) -> MITTEL BEI SÄURE BEDINGTEN ERKRANKUNGEN | X14: =LEFT(Table1[[#This Row],[Atc Code]],3) -> A02
A15: 2960 | B15: 4311843, 04311872, 00296590 | C15: 2127087 | D15: Löschmeldung | E15: 43709 | F15: 44382 | G15: =F15-E15 -> 673 | H15: 43957 | I15: 44382 | J15: Produktionsproblem | K15: RANITIDIN BASICS 150 mg | L15: A02BA02 | M15: Ranitidinhydrochlorid | N15: ja | O15: Basics GmbH | P15: 214403990 | Q15: info@basics.de | R15: Sonstige | U15: Nein | V15: Filmtablette | W15: =VLOOKUP(Table1[[#This Row],[Obergruppe ATC-Code]],Tabelle3!$A$2:$B$100,2) -> MITTEL BEI SÄURE BEDINGTEN ERKRANKUNGEN | X15: =LEFT(Table1[[#This Row],[Atc Code]],3) -> A02
A16: 3029 | B16: 7568028 | C16: 2136410 | D16: Löschmeldung | E16: 43709 | F16: 44382 | G16: =F16-E16 -> 673 | H16: 43957 | I16: 44382 | J16: Produktionsproblem | K16: RANITIDIN BASICS 300 mg | L16: A02BA02 | M16: Ranitidinhydrochlorid | N16: ja | O16: Basics GmbH | P16: 214403990 | Q16: info@basics.de | R16: Sonstige | U16: Nein | V16: Filmtablette | W16: =VLOOKUP(Table1[[#This Row],[Obergruppe ATC-Code]],Tabelle3!$A$2:$B$100,2) -> MITTEL BEI SÄURE BEDINGTEN ERKRANKUNGEN | X16: =LEFT(Table1[[#This Row],[Atc Code]],3) -> A02
A17: 2303 | B17: 07156343, 07156372, 07156389 | C17: 2134272 | D17: Änderungsmeldung | E17: 43709 | F17: 45473 | G17: =F17-E17 -> 1764 | H17: 43728 | I17: 45098 | J17: Sonstige | K17: Ranitidin-ratiopharm 300mg Filmtabletten | L17: A02BA02 | M17: Ranitidinhydrochlorid | N17: ja | O17: ratiopharm GmbH | P17: 0800 10 117 07 | Q17: marketing-gx.tevade@ratiopharm.de | R17: Sonstige | U17: Ja | V17: Filmtablette | W17: =VLOOKUP(Table1[[#This Row],[Obergruppe ATC-Code]],Tabelle3!$A$2:$B$100,2) -> MITTEL BEI SÄURE BEDINGTEN ERKRANKUNGEN | X17: =LEFT(Table1[[#This Row],[Atc Code]],3) -> A02
A18: 2302 | B18: 07156314, 07156320, 07156337 | C18: 2134278 | D18: Änderungsmeldung | E18: 43709 | F18: 45473 | G18: =F18-E18 -> 1764 | H18: 43728 | I18: 45098 | J18: Sonstige | K18: Ranitidin-ratiopharm 150mg Filmtabletten | L18: A02BA02 | M18: Ranitidinhydrochlorid | N18: ja | O18: ratiopharm GmbH | P18: 0800 10 117 07 | Q18: marketing-gx.tevade@ratiopharm.de | R18: Sonstige | U18: Ja | V18: Filmtablette | W18: =VLOOKUP(Table1[[#This Row],[Obergruppe ATC-Code]],Tabelle3!$A$2:$B$100,2) -> MITTEL BEI SÄURE BEDINGTEN ERKRANKUNGEN | X18: =LEFT(Table1[[#This Row],[Atc Code]],3) -> A02
A19: 893 | B19: 7430749 | C19: 2134537 | D19: Änderungsmeldung | E19: 43709 | F19: 45473 | G19: =F19-E19 -> 1764 | H19: 43728 | I19: 45098 | J19: Sonstige | K19: Ranitidin-ratiopharm 50mg/5ml Injektionslösung | L19: A02BA02 | M19: Ranitidinhydrochlorid | N19: ja | O19: ratiopharm GmbH | P19: 0800 10 117 07 | Q19: marketing-gx.tevade@ratiopharm.de | R19: Sonstige | U19: Ja | V19: Injektionslösung | W19: =VLOOKUP(Table1[[#This Row],[Obergruppe ATC-Code]],Tabelle3!$A$2:$B$100,2) -> MITTEL BEI SÄURE BEDINGTEN ERKRANKUNGEN | X19: =LEFT(Table1[[#This Row],[Atc Code]],3) -> A02
A20: 3028 | B20: 7258718 | C20: 2130559 | D20: Änderungsmeldung | E20: 44075 | F20: 45291 | G20: =F20-E20 -> 1216 | H20: 44104 | I20: 45120 | J20: Sonstige | K20: Ranitidin AL 300 | L20: A02BA02 | M20: Ranitidinhydrochlorid | N20: nein | O20: ALIUD PHARMA GmbH | P20: 07333/9651-0 | Q20: info@aliud.de | R20: Erhöhte Nachfrage | U20: Nein | V20: Filmtablette | W20: =VLOOKUP(Table1[[#This Row],[Obergruppe ATC-Code]],Tabelle3!$A$2:$B$100,2) -> MITTEL BEI SÄURE BEDINGTEN ERKRANKUNGEN | X20: =LEFT(Table1[[#This Row],[Atc Code]],3) -> A02
A21: 3027 | B21: 7258687 | C21: 2130558 | D21: Änderungsmeldung | E21: 44075 | F21: 45291 | G21: =F21-E21 -> 1216 | H21: 44104 | I21: 45120 | J21: Sonstige | K21: Ranitidin AL 150 | L21: A02BA02 | M21: Ranitidinhydrochlorid | N21: nein | O21: ALIUD PHARMA GmbH | P21: 07333/9651-0 | Q21: info@aliud.de | R21: Erhöhte Nachfrage | U21: Nein | V21: Filmtablette | W21: =VLOOKUP(Table1[[#This Row],[Obergruppe ATC-Code]],Tabelle3!$A$2:$B$100,2) -> MITTEL BEI SÄURE BEDINGTEN ERKRANKUNGEN | X21: =LEFT(Table1[[#This Row],[Atc Code]],3) -> A02
A22: 1813 | B22: 01016960, 01016977 | C22: 2134271 | D22: Änderungsmeldung | E22: 43709 | F22: 45473 | G22: =F22-E22 -> 1764 | H22: 43728 | I22: 45125 | J22: Sonstige | K22: Ranitidin AbZ 300mg Filmtabletten | L22: A02BA02 | M22: Ranitidinhydrochlorid | N22: nein | O22: AbZ-Pharma GmbH - Geschäftsanschrift - | P22: 0800 10 117 07 | Q22: info@ratiopharm.de | R22: Sonstige | U22: Ja | V22: Filmtablette | W22: =VLOOKUP(Table1[[#This Row],[Obergruppe ATC-Code]],Tabelle3!$A$2:$B$100,2) -> MITTEL BEI SÄURE BEDINGTEN ERKRANKUNGEN | X22: =LEFT(Table1[[#This Row],[Atc Code]],3) -> A02
A23: 165 | B23: 1016931 | C23: 2134277 | D23: Änderungsmeldung | E23: 43709 | F23: 45473 | G23: =F23-E23 -> 1764 | H23: 43728 | I23: 45125 | J23: Sonstige | K23: Ranitidin AbZ 150 mg Filmtabletten | L23: A02BA02 | M23: Ranitidinhydrochlorid | N23: ja | O23: AbZ-Pharma GmbH - Geschäftsanschrift - | P23: 0800 10 117 07 | Q23: info@ratiopharm.de | R23: Sonstige | U23: Ja | V23: Filmtablette | W23: =VLOOKUP(Table1[[#This Row],[Obergruppe ATC-Code]],Tabelle3!$A$2:$B$100,2) -> MITTEL BEI SÄURE BEDINGTEN ERKRANKUNGEN | X23: =LEFT(Table1[[#This Row],[Atc Code]],3) -> A02
A24: 97 | B24: 592704 | C24: 2142653 | D24: Löschmeldung | E24: 43800 | F24: 44074 | G24: =F24-E24 -> 274 | H24: 43803 | I24: 44047 | J24: Sonstige | K24: Famotidin STADA 20 mg Filmtabletten | L24: A02BA03 | M24: Famotidin | N24: ja | O24: STADAPHARM, Gesellschaft mit beschränkter Haftung | P24: christiane.georgi@stadapharm.de | Q24: Christiane Georgi | R24: Unzureichende Produktionskapazitäten | U24: Nein | V24: Filmtablette | W24: =VLOOKUP(Table1[[#This Row],[Obergruppe ATC-Code]],Tabelle3!$A$2:$B$100,2) -> MITTEL BEI SÄURE BEDINGTEN ERKRANKUNGEN | X24: =LEFT(Table1[[#This Row],[Atc Code]],3) -> A02
A25: 99 | B25: 592733 | C25: 2142654 | D25: Löschmeldung | E25: 43800 | F25: 44227 | G25: =F25-E25 -> 427 | H25: 43803 | I25: 44200 | J25: Sonstige | K25: Famotidin STADA 40 mg Filmtabletten | L25: A02BA03 | M25: Famotidin | N25: ja | O25: STADAPHARM, Gesellschaft mit beschränkter Haftung | P25: christiane.georgi@stadapharm.de | Q25: Christiane Georgi | R25: Unzureichende Produktionskapazitäten | U25: Nein | V25: Filmtablette | W25: =VLOOKUP(Table1[[#This Row],[Obergruppe ATC-Code]],Tabelle3!$A$2:$B$100,2) -> MITTEL BEI SÄURE BEDINGTEN ERKRANKUNGEN | X25: =LEFT(Table1[[#This Row],[Atc Code]],3) -> A02
A26: 100 | B26: 592733 | C26: 2142654 | D26: Löschmeldung | E26: 44774 | F26: 45014 | G26: =F26-E26 -> 240 | H26: 44937 | I26: 45020 | J26: Produktionsproblem | K26: Famotidin STADA 40 mg Filmtabletten | L26: A02BA03 | M26: Famotidin | N26: nein | O26: STADAPHARM, Gesellschaft mit beschränkter Haftung | Q26: christiane.georgi@stada.de | R26: Probleme in der Herstellung | S26: Neue Ware bereits geliefert. Es ist zur Zeit nur begrenzt Ware lieferfähig. Nachfrage ist größer als Lagerbestand. Ab März 2023 werden wir wieder voll lieferunfähig sein. | U26: Vorgesehen | V26: Filmtablette | W26: =VLOOKUP(Table1[[#This Row],[Obergruppe ATC-Code]],Tabelle3!$A$2:$B$100,2) -> MITTEL BEI SÄURE BEDINGTEN ERKRANKUNGEN | X26: =LEFT(Table1[[#This Row],[Atc Code]],3) -> A02
A27: 98 | B27: 592704 | C27: 2142653 | D27: Löschmeldung | E27: 44866 | F27: 45054 | G27: =F27-E27 -> 188 | H27: 44937 | I27: 45077 | J27: Produktionsproblem | K27: Famotidin STADA 20 mg Filmtabletten | L27: A02BA03 | M27: Famotidin | N27: nein | O27: STADAPHARM, Gesellschaft mit beschränkter Haftung | Q27: christiane.georgi@stada.de | R27: Probleme in der Herstellung | S27: Lieferunfähigkeit wegen hoher Überverkäufe durch out of stock Mitbewerber - Nachbestellung getätigt. Liefertermin neuer Ware wird versucht vorzuziehen. | U27: Vorgesehen | V27: Filmtablette | W27: =VLOOKUP(Table1[[#This Row],[Obergruppe ATC-Code]],Tabelle3!$A$2:$B$100,2) -> MITTEL BEI SÄURE BEDINGTEN ERKRANKUNGEN | X27: =LEFT(Table1[[#This Row],[Atc Code]],3) -> A02
A28: 1744 | B28: 00601248, 00601260 | C28: 2141619 | D28: Löschmeldung | E28: 44683 | F28: 45107 | G28: =F28-E28 -> 424 | H28: 44945 | I28: 45125 | J28: Sonstige | K28: Famotidin-ratiopharm 40 mg Filmtabletten | L28: A02BA03 | M28: Famotidin | N28: ja | O28: ratiopharm GmbH | Q28: info@ratiopharm.de | R28: Sonstige | U28: Vorgesehen | V28: Filmtablette | W28: =VLOOKUP(Table1[[#This Row],[Obergruppe ATC-Code]],Tabelle3!$A$2:$B$100,2) -> MITTEL BEI SÄURE BEDINGTEN ERKRANKUNGEN | X28: =LEFT(Table1[[#This Row],[Atc Code]],3) -> A02
A29: 1743 | B29: 00601219, 00601225 | C29: 2141599 | D29: Löschmeldung | E29: 44683 | F29: 45107 | G29: =F29-E29 -> 424 | H29: 44945 | I29: 45125 | J29: Sonstige | K29: Famotidin-ratiopharm 20 mg Filmtabletten | L29: A02BA03 | M29: Famotidin | N29: ja | O29: ratiopharm GmbH | Q29: info@ratiopharm.de | R29: Sonstige | U29: Vorgesehen | V29: Filmtablette | W29: =VLOOKUP(Table1[[#This Row],[Obergruppe ATC-Code]],Tabelle3!$A$2:$B$100,2) -> MITTEL BEI SÄURE BEDINGTEN ERKRANKUNGEN | X29: =LEFT(Table1[[#This Row],[Atc Code]],3) -> A02
A30: 1944 | B30: 02129376, 02129442, 02850352, 10549307, 10549313 | C30: 2168099 | D30: Löschmeldung | E30: 44967 | F30: 45070 | G30: =F30-E30 -> 103 | H30: 44967 | I30: 45072 | J30: Sonstige | K30: Pantoprazol Aristo 20 mg magensaftresistente Tabletten | L30: A02BC02 | M30: Pantoprazol-Natrium-Sesquihydrat | N30: nein | O30: Aristo Pharma GmbH | Q30: info@aristo-pharma.de | R30: Probleme beim Sonstigen Hersteller | U30: Vorgesehen | V30: magensaftresistente Tablette | W30: =VLOOKUP(Table1[[#This Row],[Obergruppe ATC-Code]],Tabelle3!$A$2:$B$100,2) -> MITTEL BEI SÄURE BEDINGTEN ERKRANKUNGEN | X30: =LEFT(Table1[[#This Row],[Atc Code]],3) -> A02
A31: 1945 | B31: 02129465, 02129494, 02850398, 10549336, 10549342 | C31: 2168100 | D31: Löschmeldung | E31: 44967 | F31: 45091 | G31: =F31-E31 -> 124 | H31: 44967 | I31: 45091 | J31: Sonstige | K31: Pantoprazol Aristo 40 mg magensaftresistente Tabletten | L31: A02BC02 | M31: Pantoprazol-Natrium-Sesquihydrat | N31: nein | O31: Aristo Pharma GmbH | Q31: info@aristo-pharma.de | R31: Probleme beim Sonstigen Hersteller | U31: Vorgesehen | V31: magensaftresistente Tablette | W31: =VLOOKUP(Table1[[#This Row],[Obergruppe ATC-Code]],Tabelle3!$A$2:$B$100,2) -> MITTEL BEI SÄURE BEDINGTEN ERKRANKUNGEN | X31: =LEFT(Table1[[#This Row],[Atc Code]],3) -> A02
A32: 1987 | B32: 02750225 | C32: 2158277 | D32: Löschmeldung | E32: 43800 | F32: 43861 | G32: =F32-E32 -> 61 | H32: 43770 | I32: 43819 | J32: Sonstige | K32: Nexium 40 mg Pulver zur Herstellung einer Infusionslösung | L32: A02BC05 | M32: Esomeprazol-Natrium | N32: ja | O32: AstraZeneca GmbH | P32: 0800-2288660 | Q32: service.center@astrazeneca.com | R32: Unzureichende Produktionskapazitäten | T32: Omep 40 mg Pulver zur Herstellung einer Infusionslösung - Einreichungsnummer: 2172931 | U32: Nein | V32: Pulver zur Herstellung einer Infusionslösung | W32: =VLOOKUP(Table1[[#This Row],[Obergruppe ATC-Code]],Tabelle3!$A$2:$B$100,2) -> MITTEL BEI SÄURE BEDINGTEN ERKRANKUNGEN | X32: =LEFT(Table1[[#This Row],[Atc Code]],3) -> A02
A33: 2843 | B33: 15744404, 08845234, 08845240, 08845257, 15744367, 15744373, 15744396 | C33: 2200519 | D33: Löschmeldung | E33: 43891 | F33: 44165 | G33: =F33-E33 -> 274 | H33: 43957 | I33: 44194 | J33: Produktionsproblem | K33: ESOMEPRAZOL BASICS 40 mg magensaftresistente Hartkapseln | L33: A02BC05 | M33: Esomeprazol-Hemimagnesium | N33: ja | O33: Basics GmbH | P33: 214403990 | Q33: info@basics.de | R33: Sonstige | U33: Nein | V33: magensaftresistente Hartkapsel | W33: =VLOOKUP(Table1[[#This Row],[Obergruppe ATC-Code]],Tabelle3!$A$2:$B$100,2) -> MITTEL BEI SÄURE BEDINGTEN ERKRANKUNGEN | X33: =LEFT(Table1[[#This Row],[Atc Code]],3) -> A02
A34: 2842 | B34: 15744350, 08845205, 08845211, 08845228, 15744321, 15744338, 15744344 | C34: 2200518 | D34: Löschmeldung | E34: 43891 | F34: 44165 | G34: =F34-E34 -> 274 | H34: 43957 | I34: 44194 | J34: Produktionsproblem | K34: ESOMEPRAZOL BASICS 20 mg magensaftresistente Hartkapseln | L34: A02BC05 | M34: Esomeprazol-Hemimagnesium | N34: ja | O34: Basics GmbH | P34: 214403990 | Q34: info@basics.de | R34: Sonstige | U34: Nein | V34: magensaftresistente Hartkapsel | W34: =VLOOKUP(Table1[[#This Row],[Obergruppe ATC-Code]],Tabelle3!$A$2:$B$100,2) -> MITTEL BEI SÄURE BEDINGTEN ERKRANKUNGEN | X34: =LEFT(Table1[[#This Row],[Atc Code]],3) -> A02
A35: 3031 | B35: 11068633 | C35: 2191507 | D35: Änderungsmeldung | E35: 43831 | F35: 44742 | G35: =F35-E35 -> 911 | H35: 43951 | I35: 44959 | J35: Produktionsproblem | K35: Esomeprazol-Elpen 40 mg Pulver zur Herstellung einer Injektions- bzw. Infusionslösung | L35: A02BC05 | M35: Esomeprazol-Natrium | N35: ja | O35: Elpen Pharmaceutical Co. Inc. Beiname: Elpen, Elpen S.A., Elpen A.E. | P35: 030 7974040 0 | Q35: info@elpen-pharma.de | R35: GMP Mängel | S35: Die Zulassung des Arzneimittels wurde 2022 zurück gezogen | U35: Nein | V35: Pulver zur Herstellung einer Injektions- /Infusionslösung | W35: =VLOOKUP(Table1[[#This Row],[Obergruppe ATC-Code]],Tabelle3!$A$2:$B$100,2) -> MITTEL BEI SÄURE BEDINGTEN ERKRANKUNGEN | X35: =LEFT(Table1[[#This Row],[Atc Code]],3) -> A02
A36: 1141 | B36: 9705624 | C36: 2178257 | D36: Löschmeldung | E36: 43891 | F36: 44012 | G36: =F36-E36 -> 121 | H36: 43936 | I36: 43991 | J36: Produktionsproblem | K36: Pylera 140 mg/125 mg/125 mg Hartkapseln | L36: A02BD08 | M36: Citronensäure-Bismut-Kalium-Salz (2:1:5) x H<2>O; Metronidazol; Tetracyclinhydrochlorid | N36: nein | O36: Allergan Pharmaceuticals International Limited | P36: 069 9203810 | Q36: CS-Germany@Allergan.com | R36: Sonstige | U36: Nein | V36: Hartkapsel,Pulver,Kapsel | W36: =VLOOKUP(Table1[[#This Row],[Obergruppe ATC-Code]],Tabelle3!$A$2:$B$100,2) -> MITTEL BEI SÄURE BEDINGTEN ERKRANKUNGEN | X36: =LEFT(Table1[[#This Row],[Atc Code]],3) -> A02
A37: 1142 | B37: 9705624 | C37: 2178257 | D37: Erstmeldung | E37: 45188 | F37: 45230 | G37: =F37-E37 -> 42 | H37: 45191 | I37: 45191 | J37: Sonstige | K37: Pylera 140 mg/125 mg/125 mg Hartkapseln | L37: A02BD08 | M37: Citronensäure-Bismut-Kalium-Salz (2:1:5) x H<2>O; Metronidazol; Tetracyclinhydrochlorid | N37: ja | O37: Laboratoires Juvise Pharmaceuticals | P37: +33 (0)4 26 29 40 00 | Q37: bruno.pouly@juvise.com | R37: Erhöhte Nachfrage | U37: Nein | V37: Hartkapsel,Pulver,Kapsel | W37: =VLOOKUP(Table1[[#This Row],[Obergruppe ATC-Code]],Tabelle3!$A$2:$B$100,2) -> MITTEL BEI SÄURE BEDINGTEN ERKRANKUNGEN | X37: =LEFT(Table1[[#This Row],[Atc Code]],3) -> A02
A38: 1925 | B38: 01894117, 15238954 | C38: 739722 | D38: Löschmeldung | E38: 45000 | F38: 45147 | G38: =F38-E38 -> 147 | H38: 45127 | I38: 45147 | J38: Sonstige | K38: Robinul zur Injektion | L38: A03AB02 | M38: Glycopyrroniumbromid (Ph.Eur.) | N38: ja | O38: Riemser Pharma GmbH | Q38: info.germany@esteve.com | R38: Sonstige | S38: n.a | U38: Nein | V38: Injektionslösung | W38: =VLOOKUP(Table1[[#This Row],[Obergruppe ATC-Code]],Tabelle3!$A$2:$B$100,2) -> MITTEL BEI FUNKTIONELLEN GASTROINTESTINALEN STÖRUNGEN | X38: =LEFT(Table1[[#This Row],[Atc Code]],3) -> A03
A39: 19 | B39: 85829 | C39: 5010629 | D39: Löschmeldung | E39: 44365 | F39: 44418 | G39: =F39-E39 -> 53 | H39: 44365 | I39: 44418 | J39: Sonstige | K39: Atropinum sulfuricum 0,5 mg Eifelfango | L39: A03BA01, TERM_ID_NA_2090009607 | M39: Atropinsulfat (Ph.Eur.) | N39: ja | O39: Eifelfango Chemisch Pharmazeutisches Werk GmbH & Co. KG | P39: 02641/9029382 | Q39: m.moeller@eifelfango.de | R39: Erhöhte Nachfrage | S39: zu hoher Abverkauf | U39: Vorgesehen | V39: Injektionslösung | W39: =VLOOKUP(Table1[[#This Row],[Obergruppe ATC-Code]],Tabelle3!$A$2:$B$100,2) -> MITTEL BEI FUNKTIONELLEN GASTROINTESTINALEN STÖRUNGEN | X39: =LEFT(Table1[[#This Row],[Atc Code]],3) -> A03
A40: 2576 | B40: 11052833, 12644694, 00045126 | C40: 2110156 | D40: Löschmeldung | E40: 43831 | F40: 44743 | G40: =F40-E40 -> 912 | H40: 43894 | I40: 44798 | J40: Sonstige | K40: MCP AL retard | L40: A03FA01 | M40: Metoclopramidhydrochlorid (Ph.Eur.) | N40: ja | O40: ALIUD PHARMA GmbH | P40: 07333/9651-0 | Q40: info@aliud.de | R40: Erhöhte Nachfrage | S40: Produkt wurde vom Markt genommen (AV). | U40: Nein | V40: Hartkapsel, retardiert | W40: =VLOOKUP(Table1[[#This Row],[Obergruppe ATC-Code]],Tabelle3!$A$2:$B$100,2) -> MITTEL BEI FUNKTIONELLEN GASTROINTESTINALEN STÖRUNGEN | X40: =LEFT(Table1[[#This Row],[Atc Code]],3) -> A03
...

Sheet Tabelle3
B1: Spalte1 | C1: 2017-01-01 | D1: 2017-02-01 | E1: 2017-03-01 | F1: 2017-04-01 | G1: 2017-05-01 | H1: 2017-06-01 | I1: 2017-07-01 | J1: 2017-08-01 | K1: 2017-09-01 | L1: 2017-10-01 | M1: 2017-11-01 | N1: 2017-12-01 | O1: 2018-01-01 | P1: 2018-02-01 | Q1: 2018-03-01 | R1: 2018-04-01 | S1: 2018-05-01 | T1: 2018-06-01 | U1: 2018-07-01 | V1: 2018-08-01 | W1: 2018-09-01 | X1: 2018-10-01 | Y1: 2018-11-01 | Z1: 2018-12-01 | AA1: 2019-01-01 | AB1: 2019-02-01 | AC1: 2019-03-01 | AD1: 2019-04-01 | AE1: 2019-05-01 | AF1: 2019-06-01 | AG1: 2019-07-01 | AH1: 2019-08-01 | AI1: 2019-09-01 | AJ1: 2019-10-01 | AK1: 2019-11-01 | AL1: 2019-12-01 | AM1: 2020-01-01 | AN1: 2020-02-01 | AO1: 2020-03-01 | AP1: 2020-04-01 | AQ1: 2020-05-01 | AR1: 2020-06-01 | AS1: 2020-07-01 | AT1: 2020-08-01 | AU1: 2020-09-01 | AV1: 2020-10-01 | AW1: 2020-11-01 | AX1: 2020-12-01 | AY1: 2021-01-01 | AZ1: 2021-02-01 | BA1: 2021-03-01 | BB1: 2021-04-01 | BC1: 2021-05-01 | BD1: 2021-06-01 | BE1: 2021-07-01 | BF1: 2021-08-01 | BG1: 2021-09-01 | BH1: 2021-10-01 | BI1: 2021-11-01 | BJ1: 2021-12-01 | BK1: 2022-01-01 | BL1: 2022-02-01 | BM1: 2022-03-01 | BN1: 2022-04-01 | BO1: 2022-05-01 | BP1: 2022-06-01 | BQ1: 2022-07-01 | BR1: 2022-08-01 | BS1: 2022-09-01 | BT1: 2022-10-01 | BU1: 2022-11-01 | BV1: 2022-12-01 | BW1: 2023-01-01 | BX1: 2023-02-01 | BY1: 2023-03-01 | BZ1: 2023-04-01 | CA1: 2023-05-01 | CB1: 2023-06-01 | CC1: 2023-07-01 | CD1: 2023-08-01 | CE1: 2023-09-01 | CF1: 2023-10-01 | CG1: 2023-11-01 | CH1: 2023-12-01 | CI1: 2024-01-01 | CJ1: 2024-02-01 | CK1: 2024-03-01 | CL1: 2024-04-01 | CM1: 2024-05-01 | CN1: 2024-06-01 | CO1: 2024-07-01 | CP1: 2024-08-01 | CQ1: 2024-09-01 | CR1: 2024-10-01 | CS1: 2024-11-01 | CT1: 2024-12-01
A2: A01 | B2: STOMATOLOGIKA | C2: =COUNTIFS(INDIRECT("Table1[Beginn]"),"<="&C$1,INDIRECT("Table1[Ende]"),">="&C$1,INDIRECT("Table1[Obergruppe ATC-Code]"),Tabelle3!$A2) -> 0 | D2: =COUNTIFS(INDIRECT("Table1[Beginn]"),"<="&D$1,INDIRECT("Table1[Ende]"),">="&D$1,INDIRECT("Table1[Obergruppe ATC-Code]"),Tabelle3!$A2) -> 0 | E2: =COUNTIFS(INDIRECT("Table1[Beginn]"),"<="&E$1,INDIRECT("Table1[Ende]"),">="&E$1,INDIRECT("Table1[Obergruppe ATC-Code]"),Tabelle3!$A2) -> 0 | F2: =COUNTIFS(INDIRECT("Table1[Beginn]"),"<="&F$1,INDIRECT("Table1[Ende]"),">="&F$1,INDIRECT("Table1[Obergruppe ATC-Code]"),Tabelle3!$A2) -> 0 | G2: =COUNTIFS(INDIRECT("Table1[Beginn]"),"<="&G$1,INDIRECT("Table1[Ende]"),">="&G$1,INDIRECT("Table1[Obergruppe ATC-Code]"),Tabelle3!$A2) -> 0 | H2: =COUNTIFS(INDIRECT("Table1[Beginn]"),"<="&H$1,INDIRECT("Table1[Ende]"),">="&H$1,INDIRECT("Table1[Obergruppe ATC-Code]"),Tabelle3!$A2) -> 1 | I2: =COUNTIFS(INDIRECT("Table1[Beginn]"),"<="&I$1,INDIRECT("Table1[Ende]"),">="&I$1,INDIRECT("Table1[Obergruppe ATC-Code]"),Tabelle3!$A2) -> 1 | J2: =COUNTIFS(INDIRECT("Table1[Beginn]"),"<="&J$1,INDIRECT("Table1[Ende]"),">="&J$1,INDIRECT("Table1[Obergruppe ATC-Code]"),Tabelle3!$A2) -> 0 | ... CT2: =COUNTIFS(INDIRECT("Table1[Beginn]"),"<="&CT$1,INDIRECT("Table1[Ende]"),">="&CT$1,INDIRECT("Table1[Obergruppe ATC-Code]"),Tabelle3!$A2) -> 0 | CU2: - gesamtheitlich 2020 und 2023 starke Ausreißer nach oben - 2023-Ausreßer wesentlich größer als 2020 - L01 konstant etwas höher mit leichtem Peak von 2020 bis 2023 - zwischen 2018 und 2021 C09 mit Abstand am häufigsten betroffen - J01 2023 am häufigsten betroffen - N02 ebenfalls nicht unwesentlicher Peak 2023
A3: A02 | B3: MITTEL BEI SÄURE BEDINGTEN ERKRANKUNGEN | C3: =COUNTIFS(INDIRECT("Table1[Beginn]"),"<="&C$1,INDIRECT("Table1[Ende]"),">="&C$1,INDIRECT("Table1[Obergruppe ATC-Code]"),Tabelle3!$A3) -> 0 | D3: =COUNTIFS(INDIRECT("Table1[Beginn]"),"<="&D$1,INDIRECT("Table1[Ende]"),">="&D$1,INDIRECT("Table1[Obergruppe ATC-Code]"),Tabelle3!$A3) -> 0 | E3: =COUNTIFS(INDIRECT("Table1[Beginn]"),"<="&E$1,INDIRECT("Table1[Ende]"),">="&E$1,INDIRECT("Table1[Obergruppe ATC-Code]"),Tabelle3!$A3) -> 0 | F3: =COUNTIFS(INDIRECT("Table1[Beginn]"),"<="&F$1,INDIRECT("Table1[Ende]"),">="&F$1,INDIRECT("Table1[Obergruppe ATC-Code]"),Tabelle3!$A3) -> 0 | G3: =COUNTIFS(INDIRECT("Table1[Beginn]"),"<="&G$1,INDIRECT("Table1[Ende]"),">="&G$1,INDIRECT("Table1[Obergruppe ATC-Code]"),Tabelle3!$A3) -> 0 | H3: =COUNTIFS(INDIRECT("Table1[Beginn]"),"<="&H$1,INDIRECT("Table1[Ende]"),">="&H$1,INDIRECT("Table1[Obergruppe ATC-Code]"),Tabelle3!$A3) -> 0 | I3: =COUNTIFS(INDIRECT("Table1[Beginn]"),"<="&I$1,INDIRECT("Table1[Ende]"),">="&I$1,INDIRECT("Table1[Obergruppe ATC-Code]"),Tabelle3!$A3) -> 0 | J3: =COUNTIFS(INDIRECT("Table1[Beginn]"),"<="&J$1,INDIRECT("Table1[Ende]"),">="&J$1,INDIRECT("Table1[Obergruppe ATC-Code]"),Tabelle3!$A3) -> 0 | ... CT3: =COUNTIFS(INDIRECT("Table1[Beginn]"),"<="&CT$1,INDIRECT("Table1[Ende]"),">="&CT$1,INDIRECT("Table1[Obergruppe ATC-Code]"),Tabelle3!$A3) -> 0
A4: A03 | B4: MITTEL BEI FUNKTIONELLEN GASTROINTESTINALEN STÖRUNGEN | C4: =COUNTIFS(INDIRECT("Table1[Beginn]"),"<="&C$1,INDIRECT("Table1[Ende]"),">="&C$1,INDIRECT("Table1[Obergruppe ATC-Code]"),Tabelle3!$A4) -> 0 | D4: =COUNTIFS(INDIRECT("Table1[Beginn]"),"<="&D$1,INDIRECT("Table1[Ende]"),">="&D$1,INDIRECT("Table1[Obergruppe ATC-Code]"),Tabelle3!$A4) -> 0 | E4: =COUNTIFS(INDIRECT("Table1[Beginn]"),"<="&E$1,INDIRECT("Table1[Ende]"),">="&E$1,INDIRECT("Table1[Obergruppe ATC-Code]"),Tabelle3!$A4) -> 0 | F4: =COUNTIFS(INDIRECT("Table1[Beginn]"),"<="&F$1,INDIRECT("Table1[Ende]"),">="&F$1,INDIRECT("Table1[Obergruppe ATC-Code]"),Tabelle3!$A4) -> 0 | G4: =COUNTIFS(INDIRECT("Table1[Beginn]"),"<="&G$1,INDIRECT("Table1[Ende]"),">="&G$1,INDIRECT("Table1[Obergruppe ATC-Code]"),Tabelle3!$A4) -> 0 | H4: =COUNTIFS(INDIRECT("Table1[Beginn]"),"<="&H$1,INDIRECT("Table1[Ende]"),">="&H$1,INDIRECT("Table1[Obergruppe ATC-Code]"),Tabelle3!$A4) -> 0 | I4: =COUNTIFS(INDIRECT("Table1[Beginn]"),"<="&I$1,INDIRECT("Table1[Ende]"),">="&I$1,INDIRECT("Table1[Obergruppe ATC-Code]"),Tabelle3!$A4) -> 0 | J4: =COUNTIFS(INDIRECT("Table1[Beginn]"),"<="&J$1,INDIRECT("Table1[Ende]"),">="&J$1,INDIRECT("Table1[Obergruppe ATC-Code]"),Tabelle3!$A4) -> 0 | ... CT4: =COUNTIFS(INDIRECT("Table1[Beginn]"),"<="&CT$1,INDIRECT("Table1[Ende]"),">="&CT$1,INDIRECT("Table1[Obergruppe ATC-Code]"),Tabelle3!$A4) -> 0
A5: A04 | B5: ANTIEMETIKA UND MITTEL GEGEN ÜBELKEIT | C5: =COUNTIFS(INDIRECT("Table1[Beginn]"),"<="&C$1,INDIRECT("Table1[Ende]"),">="&C$1,INDIRECT("Table1[Obergruppe ATC-Code]"),Tabelle3!$A5) -> 0 | D5: =COUNTIFS(INDIRECT("Table1[Beginn]"),"<="&D$1,INDIRECT("Table1[Ende]"),">="&D$1,INDIRECT("Table1[Obergruppe ATC-Code]"),Tabelle3!$A5) -> 0 | E5: =COUNTIFS(INDIRECT("Table1[Beginn]"),"<="&E$1,INDIRECT("Table1[Ende]"),">="&E$1,INDIRECT("Table1[Obergruppe ATC-Code]"),Tabelle3!$A5) -> 0 | F5: =COUNTIFS(INDIRECT("Table1[Beginn]"),"<="&F$1,INDIRECT("Table1[Ende]"),">="&F$1,INDIRECT("Table1[Obergruppe ATC-Code]"),Tabelle3!$A5) -> 0 | G5: =COUNTIFS(INDIRECT("Table1[Beginn]"),"<="&G$1,INDIRECT("Table1[Ende]"),">="&G$1,INDIRECT("Table1[Obergruppe ATC-Code]"),Tabelle3!$A5) -> 0 | H5: =COUNTIFS(INDIRECT("Table1[Beginn]"),"<="&H$1,INDIRECT("Table1[Ende]"),">="&H$1,INDIRECT("Table1[Obergruppe ATC-Code]"),Tabelle3!$A5) -> 0 | I5: =COUNTIFS(INDIRECT("Table1[Beginn]"),"<="&I$1,INDIRECT("Table1[Ende]"),">="&I$1,INDIRECT("Table1[Obergruppe ATC-Code]"),Tabelle3!$A5) -> 1 | J5: =COUNTIFS(INDIRECT("Table1[Beginn]"),"<="&J$1,INDIRECT("Table1[Ende]"),">="&J$1,INDIRECT("Table1[Obergruppe ATC-Code]"),Tabelle3!$A5) -> 1 | ... CT5: =COUNTIFS(INDIRECT("Table1[Beginn]"),"<="&CT$1,INDIRECT("Table1[Ende]"),">="&CT$1,INDIRECT("Table1[Obergruppe ATC-Code]"),Tabelle3!$A5) -> 0
A6: A05 | B6: GALLEN- UND LEBERTHERAPIE | C6: =COUNTIFS(INDIRECT("Table1[Beginn]"),"<="&C$1,INDIRECT("Table1[Ende]"),">="&C$1,INDIRECT("Table1[Obergruppe ATC-Code]"),Tabelle3!$A6) -> 0 | D6: =COUNTIFS(INDIRECT("Table1[Beginn]"),"<="&D$1,INDIRECT("Table1[Ende]"),">="&D$1,INDIRECT("Table1[Obergruppe ATC-Code]"),Tabelle3!$A6) -> 0 | E6: =COUNTIFS(INDIRECT("Table1[Beginn]"),"<="&E$1,INDIRECT("Table1[Ende]"),">="&E$1,INDIRECT("Table1[Obergruppe ATC-Code]"),Tabelle3!$A6) -> 0 | F6: =COUNTIFS(INDIRECT("Table1[Beginn]"),"<="&F$1,INDIRECT("Table1[Ende]"),">="&F$1,INDIRECT("Table1[Obergruppe ATC-Code]"),Tabelle3!$A6) -> 0 | G6: =COUNTIFS(INDIRECT("Table1[Beginn]"),"<="&G$1,INDIRECT("Table1[Ende]"),">="&G$1,INDIRECT("Table1[Obergruppe ATC-Code]"),Tabelle3!$A6) -> 0 | H6: =COUNTIFS(INDIRECT("Table1[Beginn]"),"<="&H$1,INDIRECT("Table1[Ende]"),">="&H$1,INDIRECT("Table1[Obergruppe ATC-Code]"),Tabelle3!$A6) -> 0 | I6: =COUNTIFS(INDIRECT("Table1[Beginn]"),"<="&I$1,INDIRECT("Table1[Ende]"),">="&I$1,INDIRECT("Table1[Obergruppe ATC-Code]"),Tabelle3!$A6) -> 0 | J6: =COUNTIFS(INDIRECT("Table1[Beginn]"),"<="&J$1,INDIRECT("Table1[Ende]"),">="&J$1,INDIRECT("Table1[Obergruppe ATC-Code]"),Tabelle3!$A6) -> 0 | ... CT6: =COUNTIFS(INDIRECT("Table1[Beginn]"),"<="&CT$1,INDIRECT("Table1[Ende]"),">="&CT$1,INDIRECT("Table1[Obergruppe ATC-Code]"),Tabelle3!$A6) -> 0
A7: A06 | B7: MITTEL GEGEN OBSTIPATION | C7: =COUNTIFS(INDIRECT("Table1[Beginn]"),"<="&C$1,INDIRECT("Table1[Ende]"),">="&C$1,INDIRECT("Table1[Obergruppe ATC-Code]"),Tabelle3!$A7) -> 0 | D7: =COUNTIFS(INDIRECT("Table1[Beginn]"),"<="&D$1,INDIRECT("Table1[Ende]"),">="&D$1,INDIRECT("Table1[Obergruppe ATC-Code]"),Tabelle3!$A7) -> 0 | E7: =COUNTIFS(INDIRECT("Table1[Beginn]"),"<="&E$1,INDIRECT("Table1[Ende]"),">="&E$1,INDIRECT("Table1[Obergruppe ATC-Code]"),Tabelle3!$A7) -> 0 | F7: =COUNTIFS(INDIRECT("Table1[Beginn]"),"<="&F$1,INDIRECT("Table1[Ende]"),">="&F$1,INDIRECT("Table1[Obergruppe ATC-Code]"),Tabelle3!$A7) -> 0 | G7: =COUNTIFS(INDIRECT("Table1[Beginn]"),"<="&G$1,INDIRECT("Table1[Ende]"),">="&G$1,INDIRECT("Table1[Obergruppe ATC-Code]"),Tabelle3!$A7) -> 0 | H7: =COUNTIFS(INDIRECT("Table1[Beginn]"),"<="&H$1,INDIRECT("Table1[Ende]"),">="&H$1,INDIRECT("Table1[Obergruppe ATC-Code]"),Tabelle3!$A7) -> 0 | I7: =COUNTIFS(INDIRECT("Table1[Beginn]"),"<="&I$1,INDIRECT("Table1[Ende]"),">="&I$1,INDIRECT("Table1[Obergruppe ATC-Code]"),Tabelle3!$A7) -> 0 | J7: =COUNTIFS(INDIRECT("Table1[Beginn]"),"<="&J$1,INDIRECT("Table1[Ende]"),">="&J$1,INDIRECT("Table1[Obergruppe ATC-Code]"),Tabelle3!$A7) -> 0 | ... CT7: =COUNTIFS(INDIRECT("Table1[Beginn]"),"<="&CT$1,INDIRECT("Table1[Ende]"),">="&CT$1,INDIRECT("Table1[Obergruppe ATC-Code]"),Tabelle3!$A7) -> 0
A8: A07 | B8: ANTIDIARRHOIKA UND INTESTINALE ANTIPHLOGISTIKA/ANTIINFEKTIVA | C8: =COUNTIFS(INDIRECT("Table1[Beginn]"),"<="&C$1,INDIRECT("Table1[Ende]"),">="&C$1,INDIRECT("Table1[Obergruppe ATC-Code]"),Tabelle3!$A8) -> 0 | D8: =COUNTIFS(INDIRECT("Table1[Beginn]"),"<="&D$1,INDIRECT("Table1[Ende]"),">="&D$1,INDIRECT("Table1[Obergruppe ATC-Code]"),Tabelle3!$A8) -> 0 | E8: =COUNTIFS(INDIRECT("Table1[Beginn]"),"<="&E$1,INDIRECT("Table1[Ende]"),">="&E$1,INDIRECT("Table1[Obergruppe ATC-Code]"),Tabelle3!$A8) -> 0 | F8: =COUNTIFS(INDIRECT("Table1[Beginn]"),"<="&F$1,INDIRECT("Table1[Ende]"),">="&F$1,INDIRECT("Table1[Obergruppe ATC-Code]"),Tabelle3!$A8) -> 0 | G8: =COUNTIFS(INDIRECT("Table1[Beginn]"),"<="&G$1,INDIRECT("Table1[Ende]"),">="&G$1,INDIRECT("Table1[Obergruppe ATC-Code]"),Tabelle3!$A8) -> 0 | H8: =COUNTIFS(INDIRECT("Table1[Beginn]"),"<="&H$1,INDIRECT("Table1[Ende]"),">="&H$1,INDIRECT("Table1[Obergruppe ATC-Code]"),Tabelle3!$A8) -> 0 | I8: =COUNTIFS(INDIRECT("Table1[Beginn]"),"<="&I$1,INDIRECT("Table1[Ende]"),">="&I$1,INDIRECT("Table1[Obergruppe ATC-Code]"),Tabelle3!$A8) -> 0 | J8: =COUNTIFS(INDIRECT("Table1[Beginn]"),"<="&J$1,INDIRECT("Table1[Ende]"),">="&J$1,INDIRECT("Table1[Obergruppe ATC-Code]"),Tabelle3!$A8) -> 0 | ... CT8: =COUNTIFS(INDIRECT("Table1[Beginn]"),"<="&CT$1,INDIRECT("Table1[Ende]"),">="&CT$1,INDIRECT("Table1[Obergruppe ATC-Code]"),Tabelle3!$A8) -> 1
A9: A08 | B9: ANTIADIPOSITA, EXKL. DIÄTETIKA | C9: =COUNTIFS(INDIRECT("Table1[Beginn]"),"<="&C$1,INDIRECT("Table1[Ende]"),">="&C$1,INDIRECT("Table1[Obergruppe ATC-Code]"),Tabelle3!$A9) -> 0 | D9: =COUNTIFS(INDIRECT("Table1[Beginn]"),"<="&D$1,INDIRECT("Table1[Ende]"),">="&D$1,INDIRECT("Table1[Obergruppe ATC-Code]"),Tabelle3!$A9) -> 0 | E9: =COUNTIFS(INDIRECT("Table1[Beginn]"),"<="&E$1,INDIRECT("Table1[Ende]"),">="&E$1,INDIRECT("Table1[Obergruppe ATC-Code]"),Tabelle3!$A9) -> 0 | F9: =COUNTIFS(INDIRECT("Table1[Beginn]"),"<="&F$1,INDIRECT("Table1[Ende]"),">="&F$1,INDIRECT("Table1[Obergruppe ATC-Code]"),Tabelle3!$A9) -> 0 | G9: =COUNTIFS(INDIRECT("Table1[Beginn]"),"<="&G$1,INDIRECT("Table1[Ende]"),">="&G$1,INDIRECT("Table1[Obergruppe ATC-Code]"),Tabelle3!$A9) -> 0 | H9: =COUNTIFS(INDIRECT("Table1[Beginn]"),"<="&H$1,INDIRECT("Table1[Ende]"),">="&H$1,INDIRECT("Table1[Obergruppe ATC-Code]"),Tabelle3!$A9) -> 0 | I9: =COUNTIFS(INDIRECT("Table1[Beginn]"),"<="&I$1,INDIRECT("Table1[Ende]"),">="&I$1,INDIRECT("Table1[Obergruppe ATC-Code]"),Tabelle3!$A9) -> 0 | J9: =COUNTIFS(INDIRECT("Table1[Beginn]"),"<="&J$1,INDIRECT("Table1[Ende]"),">="&J$1,INDIRECT("Table1[Obergruppe ATC-Code]"),Tabelle3!$A9) -> 0 | ... CT9: =COUNTIFS(INDIRECT("Table1[Beginn]"),"<="&CT$1,INDIRECT("Table1[Ende]"),">="&CT$1,INDIRECT("Table1[Obergruppe ATC-Code]"),Tabelle3!$A9) -> 0
A10: A09 | B10: DIGESTIVA, INKL. ENZYME | C10: =COUNTIFS(INDIRECT("Table1[Beginn]"),"<="&C$1,INDIRECT("Table1[Ende]"),">="&C$1,INDIRECT("Table1[Obergruppe ATC-Code]"),Tabelle3!$A10) -> 1 | D10: =COUNTIFS(INDIRECT("Table1[Beginn]"),"<="&D$1,INDIRECT("Table1[Ende]"),">="&D$1,INDIRECT("Table1[Obergruppe ATC-Code]"),Tabelle3!$A10) -> 1 | E10: =COUNTIFS(INDIRECT("Table1[Beginn]"),"<="&E$1,INDIRECT("Table1[Ende]"),">="&E$1,INDIRECT("Table1[Obergruppe ATC-Code]"),Tabelle3!$A10) -> 1 | F10: =COUNTIFS(INDIRECT("Table1[Beginn]"),"<="&F$1,INDIRECT("Table1[Ende]"),">="&F$1,INDIRECT("Table1[Obergruppe ATC-Code]"),Tabelle3!$A10) -> 1 | G10: =COUNTIFS(INDIRECT("Table1[Beginn]"),"<="&G$1,INDIRECT("Table1[Ende]"),">="&G$1,INDIRECT("Table1[Obergruppe ATC-Code]"),Tabelle3!$A10) -> 1 | H10: =COUNTIFS(INDIRECT("Table1[Beginn]"),"<="&H$1,INDIRECT("Table1[Ende]"),">="&H$1,INDIRECT("Table1[Obergruppe ATC-Code]"),Tabelle3!$A10) -> 1 | I10: =COUNTIFS(INDIRECT("Table1[Beginn]"),"<="&I$1,INDIRECT("Table1[Ende]"),">="&I$1,INDIRECT("Table1[Obergruppe ATC-Code]"),Tabelle3!$A10) -> 1 | J10: =COUNTIFS(INDIRECT("Table1[Beginn]"),"<="&J$1,INDIRECT("Table1[Ende]"),">="&J$1,INDIRECT("Table1[Obergruppe ATC-Code]"),Tabelle3!$A10) -> 1 | ... CT10: =COUNTIFS(INDIRECT("Table1[Beginn]"),"<="&CT$1,INDIRECT("Table1[Ende]"),">="&CT$1,INDIRECT("Table1[Obergruppe ATC-Code]"),Tabelle3!$A10) -> 0
A11: A10 | B11: ANTIDIABETIKA | C11: =COUNTIFS(INDIRECT("Table1[Beginn]"),"<="&C$1,INDIRECT("Table1[Ende]"),">="&C$1,INDIRECT("Table1[Obergruppe ATC-Code]"),Tabelle3!$A11) -> 0 | D11: =COUNTIFS(INDIRECT("Table1[Beginn]"),"<="&D$1,INDIRECT("Table1[Ende]"),">="&D$1,INDIRECT("Table1[Obergruppe ATC-Code]"),Tabelle3!$A11) -> 0 | E11: =COUNTIFS(INDIRECT("Table1[Beginn]"),"<="&E$1,INDIRECT("Table1[Ende]"),">="&E$1,INDIRECT("Table1[Obergruppe ATC-Code]"),Tabelle3!$A11) -> 0 | F11: =COUNTIFS(INDIRECT("Table1[Beginn]"),"<="&F$1,INDIRECT("Table1[Ende]"),">="&F$1,INDIRECT("Table1[Obergruppe ATC-Code]"),Tabelle3!$A11) -> 0 | G11: =COUNTIFS(INDIRECT("Table1[Beginn]"),"<="&G$1,INDIRECT("Table1[Ende]"),">="&G$1,INDIRECT("Table1[Obergruppe ATC-Code]"),Tabelle3!$A11) -> 0 | H11: =COUNTIFS(INDIRECT("Table1[Beginn]"),"<="&H$1,INDIRECT("Table1[Ende]"),">="&H$1,INDIRECT("Table1[Obergruppe ATC-Code]"),Tabelle3!$A11) -> 0 | I11: =COUNTIFS(INDIRECT("Table1[Beginn]"),"<="&I$1,INDIRECT("Table1[Ende]"),">="&I$1,INDIRECT("Table1[Obergruppe ATC-Code]"),Tabelle3!$A11) -> 0 | J11: =COUNTIFS(INDIRECT("Table1[Beginn]"),"<="&J$1,INDIRECT("Table1[Ende]"),">="&J$1,INDIRECT("Table1[Obergruppe ATC-Code]"),Tabelle3!$A11) -> 0 | ... CT11: =COUNTIFS(INDIRECT("Table1[Beginn]"),"<="&CT$1,INDIRECT("Table1[Ende]"),">="&CT$1,INDIRECT("Table1[Obergruppe ATC-Code]"),Tabelle3!$A11) -> 1
A12: A11 | B12: VITAMINE | C12: =COUNTIFS(INDIRECT("Table1[Beginn]"),"<="&C$1,INDIRECT("Table1[Ende]"),">="&C$1,INDIRECT("Table1[Obergruppe ATC-Code]"),Tabelle3!$A12) -> 0 | D12: =COUNTIFS(INDIRECT("Table1[Beginn]"),"<="&D$1,INDIRECT("Table1[Ende]"),">="&D$1,INDIRECT("Table1[Obergruppe ATC-Code]"),Tabelle3!$A12) -> 0 | E12: =COUNTIFS(INDIRECT("Table1[Beginn]"),"<="&E$1,INDIRECT("Table1[Ende]"),">="&E$1,INDIRECT("Table1[Obergruppe ATC-Code]"),Tabelle3!$A12) -> 0 | F12: =COUNTIFS(INDIRECT("Table1[Beginn]"),"<="&F$1,INDIRECT("Table1[Ende]"),">="&F$1,INDIRECT("Table1[Obergruppe ATC-Code]"),Tabelle3!$A12) -> 0 | G12: =COUNTIFS(INDIRECT("Table1[Beginn]"),"<="&G$1,INDIRECT("Table1[Ende]"),">="&G$1,INDIRECT("Table1[Obergruppe ATC-Code]"),Tabelle3!$A12) -> 0 | H12: =COUNTIFS(INDIRECT("Table1[Beginn]"),"<="&H$1,INDIRECT("Table1[Ende]"),">="&H$1,INDIRECT("Table1[Obergruppe ATC-Code]"),Tabelle3!$A12) -> 0 | I12: =COUNTIFS(INDIRECT("Table1[Beginn]"),"<="&I$1,INDIRECT("Table1[Ende]"),">="&I$1,INDIRECT("Table1[Obergruppe ATC-Code]"),Tabelle3!$A12) -> 0 | J12: =COUNTIFS(INDIRECT("Table1[Beginn]"),"<="&J$1,INDIRECT("Table1[Ende]"),">="&J$1,INDIRECT("Table1[Obergruppe ATC-Code]"),Tabelle3!$A12) -> 0 | ... CT12: =COUNTIFS(INDIRECT("Table1[Beginn]"),"<="&CT$1,INDIRECT("Table1[Ende]"),">="&CT$1,INDIRECT("Table1[Obergruppe ATC-Code]"),Tabelle3!$A12) -> 0
A13: A12 | B13: MINERALSTOFFE | C13: =COUNTIFS(INDIRECT("Table1[Beginn]"),"<="&C$1,INDIRECT("Table1[Ende]"),">="&C$1,INDIRECT("Table1[Obergruppe ATC-Code]"),Tabelle3!$A13) -> 0 | D13: =COUNTIFS(INDIRECT("Table1[Beginn]"),"<="&D$1,INDIRECT("Table1[Ende]"),">="&D$1,INDIRECT("Table1[Obergruppe ATC-Code]"),Tabelle3!$A13) -> 0 | E13: =COUNTIFS(INDIRECT("Table1[Beginn]"),"<="&E$1,INDIRECT("Table1[Ende]"),">="&E$1,INDIRECT("Table1[Obergruppe ATC-Code]"),Tabelle3!$A13) -> 0 | F13: =COUNTIFS(INDIRECT("Table1[Beginn]"),"<="&F$1,INDIRECT("Table1[Ende]"),">="&F$1,INDIRECT("Table1[Obergruppe ATC-Code]"),Tabelle3!$A13) -> 0 | G13: =COUNTIFS(INDIRECT("Table1[Beginn]"),"<="&G$1,INDIRECT("Table1[Ende]"),">="&G$1,INDIRECT("Table1[Obergruppe ATC-Code]"),Tabelle3!$A13) -> 0 | H13: =COUNTIFS(INDIRECT("Table1[Beginn]"),"<="&H$1,INDIRECT("Table1[Ende]"),">="&H$1,INDIRECT("Table1[Obergruppe ATC-Code]"),Tabelle3!$A13) -> 0 | I13: =COUNTIFS(INDIRECT("Table1[Beginn]"),"<="&I$1,INDIRECT("Table1[Ende]"),">="&I$1,INDIRECT("Table1[Obergruppe ATC-Code]"),Tabelle3!$A13) -> 0 | J13: =COUNTIFS(INDIRECT("Table1[Beginn]"),"<="&J$1,INDIRECT("Table1[Ende]"),">="&J$1,INDIRECT("Table1[Obergruppe ATC-Code]"),Tabelle3!$A13) -> 0 | ... CT13: =COUNTIFS(INDIRECT("Table1[Beginn]"),"<="&CT$1,INDIRECT("Table1[Ende]"),">="&CT$1,INDIRECT("Table1[Obergruppe ATC-Code]"),Tabelle3!$A13) -> 0
A14: A13 | B14: TONIKA | C14: =COUNTIFS(INDIRECT("Table1[Beginn]"),"<="&C$1,INDIRECT("Table1[Ende]"),">="&C$1,INDIRECT("Table1[Obergruppe ATC-Code]"),Tabelle3!$A14) -> 0 | D14: =COUNTIFS(INDIRECT("Table1[Beginn]"),"<="&D$1,INDIRECT("Table1[Ende]"),">="&D$1,INDIRECT("Table1[Obergruppe ATC-Code]"),Tabelle3!$A14) -> 0 | E14: =COUNTIFS(INDIRECT("Table1[Beginn]"),"<="&E$1,INDIRECT("Table1[Ende]"),">="&E$1,INDIRECT("Table1[Obergruppe ATC-Code]"),Tabelle3!$A14) -> 0 | F14: =COUNTIFS(INDIRECT("Table1[Beginn]"),"<="&F$1,INDIRECT("Table1[Ende]"),">="&F$1,INDIRECT("Table1[Obergruppe ATC-Code]"),Tabelle3!$A14) -> 0 | G14: =COUNTIFS(INDIRECT("Table1[Beginn]"),"<="&G$1,INDIRECT("Table1[Ende]"),">="&G$1,INDIRECT("Table1[Obergruppe ATC-Code]"),Tabelle3!$A14) -> 0 | H14: =COUNTIFS(INDIRECT("Table1[Beginn]"),"<="&H$1,INDIRECT("Table1[Ende]"),">="&H$1,INDIRECT("Table1[Obergruppe ATC-Code]"),Tabelle3!$A14) -> 0 | I14: =COUNTIFS(INDIRECT("Table1[Beginn]"),"<="&I$1,INDIRECT("Table1[Ende]"),">="&I$1,INDIRECT("Table1[Obergruppe ATC-Code]"),Tabelle3!$A14) -> 0 | J14: =COUNTIFS(INDIRECT("Table1[Beginn]"),"<="&J$1,INDIRECT("Table1[Ende]"),">="&J$1,INDIRECT("Table1[Obergruppe ATC-Code]"),Tabelle3!$A14) -> 0 | ... CT14: =COUNTIFS(INDIRECT("Table1[Beginn]"),"<="&CT$1,INDIRECT("Table1[Ende]"),">="&CT$1,INDIRECT("Table1[Obergruppe ATC-Code]"),Tabelle3!$A14) -> 0
... A35: D03 | B35: ZUBEREITUNGEN ZUR BEHANDLUNG VON WUNDEN UND GESCHWÜREN | C35: =COUNTIFS(INDIRECT("Table1[Beginn]"),"<="&C$1,INDIRECT("Table1[Ende]"),">="&C$1,INDIRECT("Table1[Obergruppe ATC-Code]"),Tabelle3!$A35) -> 0 | D35: =COUNTIFS(INDIRECT("Table1[Beginn]"),"<="&D$1,INDIRECT("Table1[Ende]"),">="&D$1,INDIRECT("Table1[Obergruppe ATC-Code]"),Tabelle3!$A35) -> 0 | E35: =COUNTIFS(INDIRECT("Table1[Beginn]"),"<="&E$1,INDIRECT("Table1[Ende]"),">="&E$1,INDIRECT("Table1[Obergruppe ATC-Code]"),Tabelle3!$A35) -> 0 | F35: =COUNTIFS(INDIRECT("Table1[Beginn]"),"<="&F$1,INDIRECT("Table1[Ende]"),">="&F$1,INDIRECT("Table1[Obergruppe ATC-Code]"),Tabelle3!$A35) -> 0 | G35: =COUNTIFS(INDIRECT("Table1[Beginn]"),"<="&G$1,INDIRECT("Table1[Ende]"),">="&G$1,INDIRECT("Table1[Obergruppe ATC-Code]"),Tabelle3!$A35) -> 0 | H35: =COUNTIFS(INDIRECT("Table1[Beginn]"),"<="&H$1,INDIRECT("Table1[Ende]"),">="&H$1,INDIRECT("Table1[Obergruppe ATC-Code]"),Tabelle3!$A35) -> 0 | I35: =COUNTIFS(INDIRECT("Table1[Beginn]"),"<="&I$1,INDIRECT("Table1[Ende]"),">="&I$1,INDIRECT("Table1[Obergruppe ATC-Code]"),Tabelle3!$A35) -> 0 | J35: =COUNTIFS(INDIRECT("Table1[Beginn]"),"<="&J$1,INDIRECT("Table1[Ende]"),">="&J$1,INDIRECT("Table1[Obergruppe ATC-Code]"),Tabelle3!$A35) -> 0 | ... CT35: =COUNTIFS(INDIRECT("Table1[Beginn]"),"<="&CT$1,INDIRECT("Table1[Ende]"),">="&CT$1,INDIRECT("Table1[Obergruppe ATC-Code]"),Tabelle3!$A35) -> 0
A36: D04 | B36: ANTIPRURIGINOSA, INKL. ANTIHISTAMINIKA, ANÄSTHETIKA ETC. | C36: =COUNTIFS(INDIRECT("Table1[Beginn]"),"<="&C$1,INDIRECT("Table1[Ende]"),">="&C$1,INDIRECT("Table1[Obergruppe ATC-Code]"),Tabelle3!$A36) -> 0 | D36: =COUNTIFS(INDIRECT("Table1[Beginn]"),"<="&D$1,INDIRECT("Table1[Ende]"),">="&D$1,INDIRECT("Table1[Obergruppe ATC-Code]"),Tabelle3!$A36) -> 0 | E36: =COUNTIFS(INDIRECT("Table1[Beginn]"),"<="&E$1,INDIRECT("Table1[Ende]"),">="&E$1,INDIRECT("Table1[Obergruppe ATC-Code]"),Tabelle3!$A36) -> 0 | F36: =COUNTIFS(INDIRECT("Table1[Beginn]"),"<="&F$1,INDIRECT("Table1[Ende]"),">="&F$1,INDIRECT("Table1[Obergruppe ATC-Code]"),Tabelle3!$A36) -> 0 | G36: =COUNTIFS(INDIRECT("Table1[Beginn]"),"<="&G$1,INDIRECT("Table1[Ende]"),">="&G$1,INDIRECT("Table1[Obergruppe ATC-Code]"),Tabelle3!$A36) -> 0 | H36: =COUNTIFS(INDIRECT("Table1[Beginn]"),"<="&H$1,INDIRECT("Table1[Ende]"),">="&H$1,INDIRECT("Table1[Obergruppe ATC-Code]"),Tabelle3!$A36) -> 0 | I36: =COUNTIFS(INDIRECT("Table1[Beginn]"),"<="&I$1,INDIRECT("Table1[Ende]"),">="&I$1,INDIRECT("Table1[Obergruppe ATC-Code]"),Tabelle3!$A36) -> 0 | J36: =COUNTIFS(INDIRECT("Table1[Beginn]"),"<="&J$1,INDIRECT("Table1[Ende]"),">="&J$1,INDIRECT("Table1[Obergruppe ATC-Code]"),Tabelle3!$A36) -> 0 | ... CT36: =COUNTIFS(INDIRECT("Table1[Beginn]"),"<="&CT$1,INDIRECT("Table1[Ende]"),">="&CT$1,INDIRECT("Table1[Obergruppe ATC-Code]"),Tabelle3!$A36) -> 0 | CU36: - absolute Zahlen nicht sonderlich aussagekräftig da in einer Gruppe mehr Medikamente enthalten sein können oder Relevanz verschieden sein könnte - nach 2023 sieht es nach Abklingen aus, allerdings ist dies eine Täuschung da der letzte Punkt 2024 nur Vermutungen sind - 2020 ist Corona wohl verantwortlich - 2023 Ukraine-Krieg?
A37: D05 | B37: ANTIPSORIATIKA | C37: =COUNTIFS(INDIRECT("Table1[Beginn]"),"<="&C$1,INDIRECT("Table1[Ende]"),">="&C$1,INDIRECT("Table1[Obergruppe ATC-Code]"),Tabelle3!$A37) -> 0 | D37: =COUNTIFS(INDIRECT("Table1[Beginn]"),"<="&D$1,INDIRECT("Table1[Ende]"),">="&D$1,INDIRECT("Table1[Obergruppe ATC-Code]"),Tabelle3!$A37) -> 0 | E37: =COUNTIFS(INDIRECT("Table1[Beginn]"),"<="&E$1,INDIRECT("Table1[Ende]"),">="&E$1,INDIRECT("Table1[Obergruppe ATC-Code]"),Tabelle3!$A37) -> 0 | F37: =COUNTIFS(INDIRECT("Table1[Beginn]"),"<="&F$1,INDIRECT("Table1[Ende]"),">="&F$1,INDIRECT("Table1[Obergruppe ATC-Code]"),Tabelle3!$A37) -> 0 | G37: =COUNTIFS(INDIRECT("Table1[Beginn]"),"<="&G$1,INDIRECT("Table1[Ende]"),">="&G$1,INDIRECT("Table1[Obergruppe ATC-Code]"),Tabelle3!$A37) -> 0 | H37: =COUNTIFS(INDIRECT("Table1[Beginn]"),"<="&H$1,INDIRECT("Table1[Ende]"),">="&H$1,INDIRECT("Table1[Obergruppe ATC-Code]"),Tabelle3!$A37) -> 0 | I37: =COUNTIFS(INDIRECT("Table1[Beginn]"),"<="&I$1,INDIRECT("Table1[Ende]"),">="&I$1,INDIRECT("Table1[Obergruppe ATC-Code]"),Tabelle3!$A37) -> 0 | J37: =COUNTIFS(INDIRECT("Table1[Beginn]"),"<="&J$1,INDIRECT("Table1[Ende]"),">="&J$1,INDIRECT("Table1[Obergruppe ATC-Code]"),Tabelle3!$A37) -> 0 | ... CT37: =COUNTIFS(INDIRECT("Table1[Beginn]"),"<="&CT$1,INDIRECT("Table1[Ende]"),">="&CT$1,INDIRECT("Table1[Obergruppe ATC-Code]"),Tabelle3!$A37) -> 0
A38: D06 | B38: ANTIBIOTIKA UND CHEMOTHERAPEUTIKA ZUR DERMATOLOGISCHEN ANWENDUNG | C38: =COUNTIFS(INDIRECT("Table1[Beginn]"),"<="&C$1,INDIRECT("Table1[Ende]"),">="&C$1,INDIRECT("Table1[Obergruppe ATC-Code]"),Tabelle3!$A38) -> 0 | D38: =COUNTIFS(INDIRECT("Table1[Beginn]"),"<="&D$1,INDIRECT("Table1[Ende]"),">="&D$1,INDIRECT("Table1[Obergruppe ATC-Code]"),Tabelle3!$A38) -> 0 | E38: =COUNTIFS(INDIRECT("Table1[Beginn]"),"<="&E$1,INDIRECT("Table1[Ende]"),">="&E$1,INDIRECT("Table1[Obergruppe ATC-Code]"),Tabelle3!$A38) -> 0 | F38: =COUNTIFS(INDIRECT("Table1[Beginn]"),"<="&F$1,INDIRECT("Table1[Ende]"),">="&F$1,INDIRECT("Table1[Obergruppe ATC-Code]"),Tabelle3!$A38) -> 0 | G38: =COUNTIFS(INDIRECT("Table1[Beginn]"),"<="&G$1,INDIRECT("Table1[Ende]"),">="&G$1,INDIRECT("Table1[Obergruppe ATC-Code]"),Tabelle3!$A38) -> 0 | H38: =COUNTIFS(INDIRECT("Table1[Beginn]"),"<="&H$1,INDIRECT("Table1[Ende]"),">="&H$1,INDIRECT("Table1[Obergruppe ATC-Code]"),Tabelle3!$A38) -> 0 | I38: =COUNTIFS(INDIRECT("Table1[Beginn]"),"<="&I$1,INDIRECT("Table1[Ende]"),">="&I$1,INDIRECT("Table1[Obergruppe ATC-Code]"),Tabelle3!$A38) -> 0 | J38: =COUNTIFS(INDIRECT("Table1[Beginn]"),"<="&J$1,INDIRECT("Table1[Ende]"),">="&J$1,INDIRECT("Table1[Obergruppe ATC-Code]"),Tabelle3!$A38) -> 0 | ... CT38: =COUNTIFS(INDIRECT("Table1[Beginn]"),"<="&CT$1,INDIRECT("Table1[Ende]"),">="&CT$1,INDIRECT("Table1[Obergruppe ATC-Code]"),Tabelle3!$A38) -> 0
A39: D07 | B39: CORTICOSTEROIDE, DERMATOLOGISCHE ZUBEREITUNGEN | C39: =COUNTIFS(INDIRECT("Table1[Beginn]"),"<="&C$1,INDIRECT("Table1[Ende]"),">="&C$1,INDIRECT("Table1[Obergruppe ATC-Code]"),Tabelle3!$A39) -> 0 | D39: =COUNTIFS(INDIRECT("Table1[Beginn]"),"<="&D$1,INDIRECT("Table1[Ende]"),">="&D$1,INDIRECT("Table1[Obergruppe ATC-Code]"),Tabelle3!$A39) -> 0 | E39: =COUNTIFS(INDIRECT("Table1[Beginn]"),"<="&E$1,INDIRECT("Table1[Ende]"),">="&E$1,INDIRECT("Table1[Obergruppe ATC-Code]"),Tabelle3!$A39) -> 0 | F39: =COUNTIFS(INDIRECT("Table1[Beginn]"),"<="&F$1,INDIRECT("Table1[Ende]"),">="&F$1,INDIRECT("Table1[Obergruppe ATC-Code]"),Tabelle3!$A39) -> 2 | G39: =COUNTIFS(INDIRECT("Table1[Beginn]"),"<="&G$1,INDIRECT("Table1[Ende]"),">="&G$1,INDIRECT("Table1[Obergruppe ATC-Code]"),Tabelle3!$A39) -> 2 | H39: =COUNTIFS(INDIRECT("Table1[Beginn]"),"<="&H$1,INDIRECT("Table1[Ende]"),">="&H$1,INDIRECT("Table1[Obergruppe ATC-Code]"),Tabelle3!$A39) -> 2 | I39: =COUNTIFS(INDIRECT("Table1[Beginn]"),"<="&I$1,INDIRECT("Table1[Ende]"),">="&I$1,INDIRECT("Table1[Obergruppe ATC-Code]"),Tabelle3!$A39) -> 2 | J39: =COUNTIFS(INDIRECT("Table1[Beginn]"),"<="&J$1,INDIRECT("Table1[Ende]"),">="&J$1,INDIRECT("Table1[Obergruppe ATC-Code]"),Tabelle3!$A39) -> 2 | ... CT39: =COUNTIFS(INDIRECT("Table1[Beginn]"),"<="&CT$1,INDIRECT("Table1[Ende]"),">="&CT$1,INDIRECT("Table1[Obergruppe ATC-Code]"),Tabelle3!$A39) -> 0
A40: D08 | B40: ANTISEPTIKA UND DESINFEKTIONSMITTEL | C40: =COUNTIFS(INDIRECT("Table1[Beginn]"),"<="&C$1,INDIRECT("Table1[Ende]"),">="&C$1,INDIRECT("Table1[Obergruppe ATC-Code]"),Tabelle3!$A40) -> 0 | D40: =COUNTIFS(INDIRECT("Table1[Beginn]"),"<="&D$1,INDIRECT("Table1[Ende]"),">="&D$1,INDIRECT("Table1[Obergruppe ATC-Code]"),Tabelle3!$A40) -> 0 | E40: =COUNTIFS(INDIRECT("Table1[Beginn]"),"<="&E$1,INDIRECT("Table1[Ende]"),">="&E$1,INDIRECT("Table1[Obergruppe ATC-Code]"),Tabelle3!$A40) -> 0 | F40: =COUNTIFS(INDIRECT("Table1[Beginn]"),"<="&F$1,INDIRECT("Table1[Ende]"),">="&F$1,INDIRECT("Table1[Obergruppe ATC-Code]"),Tabelle3!$A40) -> 0 | G40: =COUNTIFS(INDIRECT("Table1[Beginn]"),"<="&G$1,INDIRECT("Table1[Ende]"),">="&G$1,INDIRECT("Table1[Obergruppe ATC-Code]"),Tabelle3!$A40) -> 0 | H40: =COUNTIFS(INDIRECT("Table1[Beginn]"),"<="&H$1,INDIRECT("Table1[Ende]"),">="&H$1,INDIRECT("Table1[Obergruppe ATC-Code]"),Tabelle3!$A40) -> 0 | I40: =COUNTIFS(INDIRECT("Table1[Beginn]"),"<="&I$1,INDIRECT("Table1[Ende]"),">="&I$1,INDIRECT("Table1[Obergruppe ATC-Code]"),Tabelle3!$A40) -> 0 | J40: =COUNTIFS(INDIRECT("Table1[Beginn]"),"<="&J$1,INDIRECT("Table1[Ende]"),">="&J$1,INDIRECT("Table1[Obergruppe ATC-Code]"),Tabelle3!$A40) -> 0 | ... CT40: =COUNTIFS(INDIRECT("Table1[Beginn]"),"<="&CT$1,INDIRECT("Table1[Ende]"),">="&CT$1,INDIRECT("Table1[Obergruppe ATC-Code]"),Tabelle3!$A40) -> 0
A41: D09 | B41: MEDIZINISCHE VERBÄNDE | C41: =COUNTIFS(INDIRECT("Table1[Beginn]"),"<="&C$1,INDIRECT("Table1[Ende]"),">="&C$1,INDIRECT("Table1[Obergruppe ATC-Code]"),Tabelle3!$A41) -> 0 | D41: =COUNTIFS(INDIRECT("Table1[Beginn]"),"<="&D$1,INDIRECT("Table1[Ende]"),">="&D$1,INDIRECT("Table1[Obergruppe ATC-Code]"),Tabelle3!$A41) -> 0 | E41: =COUNTIFS(INDIRECT("Table1[Beginn]"),"<="&E$1,INDIRECT("Table1[Ende]"),">="&E$1,INDIRECT("Table1[Obergruppe ATC-Code]"),Tabelle3!$A41) -> 0 | F41: =COUNTIFS(INDIRECT("Table1[Beginn]"),"<="&F$1,INDIRECT("Table1[Ende]"),">="&F$1,INDIRECT("Table1[Obergruppe ATC-Code]"),Tabelle3!$A41) -> 0 | G41: =COUNTIFS(INDIRECT("Table1[Beginn]"),"<="&G$1,INDIRECT("Table1[Ende]"),">="&G$1,INDIRECT("Table1[Obergruppe ATC-Code]"),Tabelle3!$A41) -> 0 | H41: =COUNTIFS(INDIRECT("Table1[Beginn]"),"<="&H$1,INDIRECT("Table1[Ende]"),">="&H$1,INDIRECT("Table1[Obergruppe ATC-Code]"),Tabelle3!$A41) -> 0 | I41: =COUNTIFS(INDIRECT("Table1[Beginn]"),"<="&I$1,INDIRECT("Table1[Ende]"),">="&I$1,INDIRECT("Table1[Obergruppe ATC-Code]"),Tabelle3!$A41) -> 0 | J41: =COUNTIFS(INDIRECT("Table1[Beginn]"),"<="&J$1,INDIRECT("Table1[Ende]"),">="&J$1,INDIRECT("Table1[Obergruppe ATC-Code]"),Tabelle3!$A41) -> 0 | ... CT41: =COUNTIFS(INDIRECT("Table1[Beginn]"),"<="&CT$1,INDIRECT("Table1[Ende]"),">="&CT$1,INDIRECT("Table1[Obergruppe ATC-Code]"),Tabelle3!$A41) -> 0
A42: D10 | B42: AKNEMITTEL | C42: =COUNTIFS(INDIRECT("Table1[Beginn]"),"<="&C$1,INDIRECT("Table1[Ende]"),">="&C$1,INDIRECT("Table1[Obergruppe ATC-Code]"),Tabelle3!$A42) -> 0 | D42: =COUNTIFS(INDIRECT("Table1[Beginn]"),"<="&D$1,INDIRECT("Table1[Ende]"),">="&D$1,INDIRECT("Table1[Obergruppe ATC-Code]"),Tabelle3!$A42) -> 0 | E42: =COUNTIFS(INDIRECT("Table1[Beginn]"),"<="&E$1,INDIRECT("Table1[Ende]"),">="&E$1,INDIRECT("Table1[Obergruppe ATC-Code]"),Tabelle3!$A42) -> 0 | F42: =COUNTIFS(INDIRECT("Table1[Beginn]"),"<="&F$1,INDIRECT("Table1[Ende]"),">="&F$1,INDIRECT("Table1[Obergruppe ATC-Code]"),Tabelle3!$A42) -> 0 | G42: =COUNTIFS(INDIRECT("Table1[Beginn]"),"<="&G$1,INDIRECT("Table1[Ende]"),">="&G$1,INDIRECT("Table1[Obergruppe ATC-Code]"),Tabelle3!$A42) -> 0 | H42: =COUNTIFS(INDIRECT("Table1[Beginn]"),"<="&H$1,INDIRECT("Table1[Ende]"),">="&H$1,INDIRECT("Table1[Obergruppe ATC-Code]"),Tabelle3!$A42) -> 0 | I42: =COUNTIFS(INDIRECT("Table1[Beginn]"),"<="&I$1,INDIRECT("Table1[Ende]"),">="&I$1,INDIRECT("Table1[Obergruppe ATC-Code]"),Tabelle3!$A42) -> 0 | J42: =COUNTIFS(INDIRECT("Table1[Beginn]"),"<="&J$1,INDIRECT("Table1[Ende]"),">="&J$1,INDIRECT("Table1[Obergruppe ATC-Code]"),Tabelle3!$A42) -> 0 | ... CT42: =COUNTIFS(INDIRECT("Table1[Beginn]"),"<="&CT$1,INDIRECT("Table1[Ende]"),">="&CT$1,INDIRECT("Table1[Obergruppe ATC-Code]"),Tabelle3!$A42) -> 0
A43: D11 | B43: ANDERE DERMATIKA | C43: =COUNTIFS(INDIRECT("Table1[Beginn]"),"<="&C$1,INDIRECT("Table1[Ende]"),">="&C$1,INDIRECT("Table1[Obergruppe ATC-Code]"),Tabelle3!$A43) -> 0 | D43: =COUNTIFS(INDIRECT("Table1[Beginn]"),"<="&D$1,INDIRECT("Table1[Ende]"),">="&D$1,INDIRECT("Table1[Obergruppe ATC-Code]"),Tabelle3!$A43) -> 0 | E43: =COUNTIFS(INDIRECT("Table1[Beginn]"),"<="&E$1,INDIRECT("Table1[Ende]"),">="&E$1,INDIRECT("Table1[Obergruppe ATC-Code]"),Tabelle3!$A43) -> 0 | F43: =COUNTIFS(INDIRECT("Table1[Beginn]"),"<="&F$1,INDIRECT("Table1[Ende]"),">="&F$1,INDIRECT("Table1[Obergruppe ATC-Code]"),Tabelle3!$A43) -> 0 | G43: =COUNTIFS(INDIRECT("Table1[Beginn]"),"<="&G$1,INDIRECT("Table1[Ende]"),">="&G$1,INDIRECT("Table1[Obergruppe ATC-Code]"),Tabelle3!$A43) -> 0 | H43: =COUNTIFS(INDIRECT("Table1[Beginn]"),"<="&H$1,INDIRECT("Table1[Ende]"),">="&H$1,INDIRECT("Table1[Obergruppe ATC-Code]"),Tabelle3!$A43) -> 0 | I43: =COUNTIFS(INDIRECT("Table1[Beginn]"),"<="&I$1,INDIRECT("Table1[Ende]"),">="&I$1,INDIRECT("Table1[Obergruppe ATC-Code]"),Tabelle3!$A43) -> 0 | J43: =COUNTIFS(INDIRECT("Table1[Beginn]"),"<="&J$1,INDIRECT("Table1[Ende]"),">="&J$1,INDIRECT("Table1[Obergruppe ATC-Code]"),Tabelle3!$A43) -> 0 | ... CT43: =COUNTIFS(INDIRECT("Table1[Beginn]"),"<="&CT$1,INDIRECT("Table1[Ende]"),">="&CT$1,INDIRECT("Table1[Obergruppe ATC-Code]"),Tabelle3!$A43) -> 0
A44: G01 | B44: GYNÄKOLOGISCHE ANTIINFEKTIVA UND ANTISEPTIKA | C44: =COUNTIFS(INDIRECT("Table1[Beginn]"),"<="&C$1,INDIRECT("Table1[Ende]"),">="&C$1,INDIRECT("Table1[Obergruppe ATC-Code]"),Tabelle3!$A44) -> 0 | D44: =COUNTIFS(INDIRECT("Table1[Beginn]"),"<="&D$1,INDIRECT("Table1[Ende]"),">="&D$1,INDIRECT("Table1[Obergruppe ATC-Code]"),Tabelle3!$A44) -> 0 | E44: =COUNTIFS(INDIRECT("Table1[Beginn]"),"<="&E$1,INDIRECT("Table1[Ende]"),">="&E$1,INDIRECT("Table1[Obergruppe ATC-Code]"),Tabelle3!$A44) -> 0 | F44: =COUNTIFS(INDIRECT("Table1[Beginn]"),"<="&F$1,INDIRECT("Table1[Ende]"),">="&F$1,INDIRECT("Table1[Obergruppe ATC-Code]"),Tabelle3!$A44) -> 0 | G44: =COUNTIFS(INDIRECT("Table1[Beginn]"),"<="&G$1,INDIRECT("Table1[Ende]"),">="&G$1,INDIRECT("Table1[Obergruppe ATC-Code]"),Tabelle3!$A44) -> 0 | H44: =COUNTIFS(INDIRECT("Table1[Beginn]"),"<="&H$1,INDIRECT("Table1[Ende]"),">="&H$1,INDIRECT("Table1[Obergruppe ATC-Code]"),Tabelle3!$A44) -> 0 | I44: =COUNTIFS(INDIRECT("Table1[Beginn]"),"<="&I$1,INDIRECT("Table1[Ende]"),">="&I$1,INDIRECT("Table1[Obergruppe ATC-Code]"),Tabelle3!$A44) -> 0 | J44: =COUNTIFS(INDIRECT("Table1[Beginn]"),"<="&J$1,INDIRECT("Table1[Ende]"),">="&J$1,INDIRECT("Table1[Obergruppe ATC-Code]"),Tabelle3!$A44) -> 0 | ... CT44: =COUNTIFS(INDIRECT("Table1[Beginn]"),"<="&CT$1,INDIRECT("Table1[Ende]"),">="&CT$1,INDIRECT("Table1[Obergruppe ATC-Code]"),Tabelle3!$A44) -> 0
A45: G02 | B45: ANDERE GYNÄKOLOGIKA | C45: =COUNTIFS(INDIRECT("Table1[Beginn]"),"<="&C$1,INDIRECT("Table1[Ende]"),">="&C$1,INDIRECT("Table1[Obergruppe ATC-Code]"),Tabelle3!$A45) -> 0 | D45: =COUNTIFS(INDIRECT("Table1[Beginn]"),"<="&D$1,INDIRECT("Table1[Ende]"),">="&D$1,INDIRECT("Table1[Obergruppe ATC-Code]"),Tabelle3!$A45) -> 0 | E45: =COUNTIFS(INDIRECT("Table1[Beginn]"),"<="&E$1,INDIRECT("Table1[Ende]"),">="&E$1,INDIRECT("Table1[Obergruppe ATC-Code]"),Tabelle3!$A45) -> 0 | F45: =COUNTIFS(INDIRECT("Table1[Beginn]"),"<="&F$1,INDIRECT("Table1[Ende]"),">="&F$1,INDIRECT("Table1[Obergruppe ATC-Code]"),Tabelle3!$A45) -> 0 | G45: =COUNTIFS(INDIRECT("Table1[Beginn]"),"<="&G$1,INDIRECT("Table1[Ende]"),">="&G$1,INDIRECT("Table1[Obergruppe ATC-Code]"),Tabelle3!$A45) -> 0 | H45: =COUNTIFS(INDIRECT("Table1[Beginn]"),"<="&H$1,INDIRECT("Table1[Ende]"),">="&H$1,INDIRECT("Table1[Obergruppe ATC-Code]"),Tabelle3!$A45) -> 0 | I45: =COUNTIFS(INDIRECT("Table1[Beginn]"),"<="&I$1,INDIRECT("Table1[Ende]"),">="&I$1,INDIRECT("Table1[Obergruppe ATC-Code]"),Tabelle3!$A45) -> 0 | J45: =COUNTIFS(INDIRECT("Table1[Beginn]"),"<="&J$1,INDIRECT("Table1[Ende]"),">="&J$1,INDIRECT("Table1[Obergruppe ATC-Code]"),Tabelle3!$A45) -> 0 | ... CT45: =COUNTIFS(INDIRECT("Table1[Beginn]"),"<="&CT$1,INDIRECT("Table1[Ende]"),">="&CT$1,INDIRECT("Table1[Obergruppe ATC-Code]"),Tabelle3!$A45) -> 0
